 2019-09-18 07:44:05,282 [P18452/D2/T1] INFO  Umbraco.Core.CoreBootManager - Umbraco 7.15.3 application starting on PTL10JCESCOBOSA
 2019-09-18 07:44:05,329 [P18452/D2/T1] INFO  Umbraco.Core.PluginManager - Determining hash of code files on disk
 2019-09-18 07:44:05,350 [P18452/D2/T1] INFO  Umbraco.Core.PluginManager - Hash determined (took 20ms)
 2019-09-18 07:44:05,551 [P18452/D2/T1] INFO  Umbraco.Core.MainDom - Acquiring MainDom...
 2019-09-18 07:44:05,554 [P18452/D2/T1] INFO  Umbraco.Core.MainDom - Acquired MainDom.
 2019-09-18 07:44:05,561 [P18452/D2/T1] INFO  Umbraco.Core.PluginManager - Resolving umbraco.interfaces.IDiscoverable
 2019-09-18 07:44:06,327 [P18452/D2/T1] INFO  Umbraco.Core.PluginManager - Resolved umbraco.interfaces.IDiscoverable (took 766ms)
 2019-09-18 07:44:06,327 [P18452/D2/T1] INFO  Umbraco.Core.PluginManager - Resolving umbraco.interfaces.IApplicationStartupHandler
 2019-09-18 07:44:06,335 [P18452/D2/T1] INFO  Umbraco.Core.PluginManager - Resolved umbraco.interfaces.IApplicationStartupHandler (took 7ms)
 2019-09-18 07:44:06,365 [P18452/D2/T1] INFO  Umbraco.Core.PluginManager - Resolving umbraco.interfaces.IDiscoverable
 2019-09-18 07:44:06,366 [P18452/D2/T1] INFO  Umbraco.Core.PluginManager - Resolved umbraco.interfaces.IDiscoverable (took 0ms)
 2019-09-18 07:44:06,366 [P18452/D2/T1] INFO  Umbraco.Core.PluginManager - Resolving Umbraco.Core.PropertyEditors.IPropertyEditorValueConverter
 2019-09-18 07:44:06,371 [P18452/D2/T1] INFO  Umbraco.Core.PluginManager - Resolved Umbraco.Core.PropertyEditors.IPropertyEditorValueConverter (took 4ms)
 2019-09-18 07:44:06,373 [P18452/D2/T1] INFO  Umbraco.Core.PluginManager - Resolving umbraco.interfaces.IDiscoverable
 2019-09-18 07:44:06,373 [P18452/D2/T1] INFO  Umbraco.Core.PluginManager - Resolved umbraco.interfaces.IDiscoverable (took 0ms)
 2019-09-18 07:44:06,374 [P18452/D2/T1] INFO  Umbraco.Core.PluginManager - Resolving Umbraco.Core.PropertyEditors.IPropertyValueConverter
 2019-09-18 07:44:06,381 [P18452/D2/T1] INFO  Umbraco.Core.PluginManager - Resolved Umbraco.Core.PropertyEditors.IPropertyValueConverter (took 7ms)
 2019-09-18 07:44:06,400 [P18452/D2/T1] INFO  Umbraco.Core.PluginManager - Resolving umbraco.interfaces.IDiscoverable
 2019-09-18 07:44:06,400 [P18452/D2/T1] INFO  Umbraco.Core.PluginManager - Resolved umbraco.interfaces.IDiscoverable (took 0ms)
 2019-09-18 07:44:06,400 [P18452/D2/T1] INFO  Umbraco.Core.PluginManager - Resolving Umbraco.Web.Mvc.SurfaceController
 2019-09-18 07:44:06,410 [P18452/D2/T1] INFO  Umbraco.Core.PluginManager - Resolved Umbraco.Web.Mvc.SurfaceController (took 9ms)
 2019-09-18 07:44:06,412 [P18452/D2/T1] INFO  Umbraco.Core.PluginManager - Resolving umbraco.interfaces.IDiscoverable
 2019-09-18 07:44:06,413 [P18452/D2/T1] INFO  Umbraco.Core.PluginManager - Resolved umbraco.interfaces.IDiscoverable (took 0ms)
 2019-09-18 07:44:06,413 [P18452/D2/T1] INFO  Umbraco.Core.PluginManager - Resolving Umbraco.Web.WebApi.UmbracoApiController
 2019-09-18 07:44:06,422 [P18452/D2/T1] INFO  Umbraco.Core.PluginManager - Resolved Umbraco.Web.WebApi.UmbracoApiController (took 8ms)
 2019-09-18 07:44:37,772 [P18452/D2/T1] WARN  Umbraco.Core.Persistence.DbConnectionExtensions - Configured database is reporting as not being available! DataSource: 192.168.1.2, InitialCatalog: UMBRACOTESTING. Exception: System.Data.SqlClient.SqlException (0x80131904): Error relacionado con la red o específico de la instancia mientras se establecía una conexión con el servidor SQL Server. No se encontró el servidor o éste no estaba accesible. Compruebe que el nombre de la instancia es correcto y que SQL Server está configurado para admitir conexiones remotas. (provider: Named Pipes Provider, error: 40 - No se pudo abrir una conexión con SQL Server) ---> System.ComponentModel.Win32Exception (0x80004005): No se ha encontrado la ruta de acceso de la red
   en System.Data.SqlClient.SqlInternalConnectionTds..ctor(DbConnectionPoolIdentity identity, SqlConnectionString connectionOptions, SqlCredential credential, Object providerInfo, String newPassword, SecureString newSecurePassword, Boolean redirectedUserInstance, SqlConnectionString userConnectionOptions, SessionData reconnectSessionData, DbConnectionPool pool, String accessToken, Boolean applyTransientFaultHandling, SqlAuthenticationProviderManager sqlAuthProviderManager)
   en System.Data.SqlClient.SqlConnectionFactory.CreateConnection(DbConnectionOptions options, DbConnectionPoolKey poolKey, Object poolGroupProviderInfo, DbConnectionPool pool, DbConnection owningConnection, DbConnectionOptions userOptions)
   en System.Data.ProviderBase.DbConnectionFactory.CreatePooledConnection(DbConnectionPool pool, DbConnection owningObject, DbConnectionOptions options, DbConnectionPoolKey poolKey, DbConnectionOptions userOptions)
   en System.Data.ProviderBase.DbConnectionPool.CreateObject(DbConnection owningObject, DbConnectionOptions userOptions, DbConnectionInternal oldConnection)
   en System.Data.ProviderBase.DbConnectionPool.UserCreateRequest(DbConnection owningObject, DbConnectionOptions userOptions, DbConnectionInternal oldConnection)
   en System.Data.ProviderBase.DbConnectionPool.TryGetConnection(DbConnection owningObject, UInt32 waitForMultipleObjectsTimeout, Boolean allowCreate, Boolean onlyOneCheckConnection, DbConnectionOptions userOptions, DbConnectionInternal& connection)
   en System.Data.ProviderBase.DbConnectionPool.TryGetConnection(DbConnection owningObject, TaskCompletionSource`1 retry, DbConnectionOptions userOptions, DbConnectionInternal& connection)
   en System.Data.ProviderBase.DbConnectionFactory.TryGetConnection(DbConnection owningConnection, TaskCompletionSource`1 retry, DbConnectionOptions userOptions, DbConnectionInternal oldConnection, DbConnectionInternal& connection)
   en System.Data.ProviderBase.DbConnectionInternal.TryOpenConnectionInternal(DbConnection outerConnection, DbConnectionFactory connectionFactory, TaskCompletionSource`1 retry, DbConnectionOptions userOptions)
   en System.Data.ProviderBase.DbConnectionClosed.TryOpenConnection(DbConnection outerConnection, DbConnectionFactory connectionFactory, TaskCompletionSource`1 retry, DbConnectionOptions userOptions)
   en System.Data.SqlClient.SqlConnection.TryOpenInner(TaskCompletionSource`1 retry)
   en System.Data.SqlClient.SqlConnection.TryOpen(TaskCompletionSource`1 retry)
   en System.Data.SqlClient.SqlConnection.Open()
   en Umbraco.Core.Persistence.DbConnectionExtensions.IsAvailable(IDbConnection connection)
ClientConnectionId:00000000-0000-0000-0000-000000000000
Error Number:53,State:0,Class:20
 2019-09-18 07:44:37,773 [P18452/D2/T1] INFO  Umbraco.Core.DatabaseContext - CanConnect = False
 2019-09-18 07:44:38,021 [P18452/D2/T1] WARN  Umbraco.Core.Persistence.DbConnectionExtensions - Configured database is reporting as not being available! DataSource: 192.168.1.2, InitialCatalog: UMBRACOTESTING. Exception: System.Data.SqlClient.SqlException (0x80131904): Error relacionado con la red o específico de la instancia mientras se establecía una conexión con el servidor SQL Server. No se encontró el servidor o éste no estaba accesible. Compruebe que el nombre de la instancia es correcto y que SQL Server está configurado para admitir conexiones remotas. (provider: Named Pipes Provider, error: 40 - No se pudo abrir una conexión con SQL Server) ---> System.ComponentModel.Win32Exception (0x80004005): No se ha encontrado la ruta de acceso de la red
   en System.Data.ProviderBase.DbConnectionPool.TryGetConnection(DbConnection owningObject, UInt32 waitForMultipleObjectsTimeout, Boolean allowCreate, Boolean onlyOneCheckConnection, DbConnectionOptions userOptions, DbConnectionInternal& connection)
   en System.Data.ProviderBase.DbConnectionPool.TryGetConnection(DbConnection owningObject, TaskCompletionSource`1 retry, DbConnectionOptions userOptions, DbConnectionInternal& connection)
   en System.Data.ProviderBase.DbConnectionFactory.TryGetConnection(DbConnection owningConnection, TaskCompletionSource`1 retry, DbConnectionOptions userOptions, DbConnectionInternal oldConnection, DbConnectionInternal& connection)
   en System.Data.ProviderBase.DbConnectionInternal.TryOpenConnectionInternal(DbConnection outerConnection, DbConnectionFactory connectionFactory, TaskCompletionSource`1 retry, DbConnectionOptions userOptions)
   en System.Data.ProviderBase.DbConnectionClosed.TryOpenConnection(DbConnection outerConnection, DbConnectionFactory connectionFactory, TaskCompletionSource`1 retry, DbConnectionOptions userOptions)
   en System.Data.SqlClient.SqlConnection.TryOpenInner(TaskCompletionSource`1 retry)
   en System.Data.SqlClient.SqlConnection.TryOpen(TaskCompletionSource`1 retry)
   en System.Data.SqlClient.SqlConnection.Open()
   en Umbraco.Core.Persistence.DbConnectionExtensions.IsAvailable(IDbConnection connection)
ClientConnectionId:00000000-0000-0000-0000-000000000000
Error Number:53,State:0,Class:20
 2019-09-18 07:44:38,021 [P18452/D2/T1] INFO  Umbraco.Core.DatabaseContext - CanConnect = False
 2019-09-18 07:44:39,023 [P18452/D2/T1] WARN  Umbraco.Core.Persistence.DbConnectionExtensions - Configured database is reporting as not being available! DataSource: 192.168.1.2, InitialCatalog: UMBRACOTESTING. Exception: System.Data.SqlClient.SqlException (0x80131904): Error relacionado con la red o específico de la instancia mientras se establecía una conexión con el servidor SQL Server. No se encontró el servidor o éste no estaba accesible. Compruebe que el nombre de la instancia es correcto y que SQL Server está configurado para admitir conexiones remotas. (provider: Named Pipes Provider, error: 40 - No se pudo abrir una conexión con SQL Server) ---> System.ComponentModel.Win32Exception (0x80004005): No se ha encontrado la ruta de acceso de la red
   en System.Data.ProviderBase.DbConnectionPool.TryGetConnection(DbConnection owningObject, UInt32 waitForMultipleObjectsTimeout, Boolean allowCreate, Boolean onlyOneCheckConnection, DbConnectionOptions userOptions, DbConnectionInternal& connection)
   en System.Data.ProviderBase.DbConnectionPool.TryGetConnection(DbConnection owningObject, TaskCompletionSource`1 retry, DbConnectionOptions userOptions, DbConnectionInternal& connection)
   en System.Data.ProviderBase.DbConnectionFactory.TryGetConnection(DbConnection owningConnection, TaskCompletionSource`1 retry, DbConnectionOptions userOptions, DbConnectionInternal oldConnection, DbConnectionInternal& connection)
   en System.Data.ProviderBase.DbConnectionInternal.TryOpenConnectionInternal(DbConnection outerConnection, DbConnectionFactory connectionFactory, TaskCompletionSource`1 retry, DbConnectionOptions userOptions)
   en System.Data.ProviderBase.DbConnectionClosed.TryOpenConnection(DbConnection outerConnection, DbConnectionFactory connectionFactory, TaskCompletionSource`1 retry, DbConnectionOptions userOptions)
   en System.Data.SqlClient.SqlConnection.TryOpenInner(TaskCompletionSource`1 retry)
   en System.Data.SqlClient.SqlConnection.TryOpen(TaskCompletionSource`1 retry)
   en System.Data.SqlClient.SqlConnection.Open()
   en Umbraco.Core.Persistence.DbConnectionExtensions.IsAvailable(IDbConnection connection)
ClientConnectionId:00000000-0000-0000-0000-000000000000
Error Number:53,State:0,Class:20
 2019-09-18 07:44:39,024 [P18452/D2/T1] INFO  Umbraco.Core.DatabaseContext - CanConnect = False
 2019-09-18 07:44:40,026 [P18452/D2/T1] WARN  Umbraco.Core.Persistence.DbConnectionExtensions - Configured database is reporting as not being available! DataSource: 192.168.1.2, InitialCatalog: UMBRACOTESTING. Exception: System.Data.SqlClient.SqlException (0x80131904): Error relacionado con la red o específico de la instancia mientras se establecía una conexión con el servidor SQL Server. No se encontró el servidor o éste no estaba accesible. Compruebe que el nombre de la instancia es correcto y que SQL Server está configurado para admitir conexiones remotas. (provider: Named Pipes Provider, error: 40 - No se pudo abrir una conexión con SQL Server) ---> System.ComponentModel.Win32Exception (0x80004005): No se ha encontrado la ruta de acceso de la red
   en System.Data.ProviderBase.DbConnectionPool.TryGetConnection(DbConnection owningObject, UInt32 waitForMultipleObjectsTimeout, Boolean allowCreate, Boolean onlyOneCheckConnection, DbConnectionOptions userOptions, DbConnectionInternal& connection)
   en System.Data.ProviderBase.DbConnectionPool.TryGetConnection(DbConnection owningObject, TaskCompletionSource`1 retry, DbConnectionOptions userOptions, DbConnectionInternal& connection)
   en System.Data.ProviderBase.DbConnectionFactory.TryGetConnection(DbConnection owningConnection, TaskCompletionSource`1 retry, DbConnectionOptions userOptions, DbConnectionInternal oldConnection, DbConnectionInternal& connection)
   en System.Data.ProviderBase.DbConnectionInternal.TryOpenConnectionInternal(DbConnection outerConnection, DbConnectionFactory connectionFactory, TaskCompletionSource`1 retry, DbConnectionOptions userOptions)
   en System.Data.ProviderBase.DbConnectionClosed.TryOpenConnection(DbConnection outerConnection, DbConnectionFactory connectionFactory, TaskCompletionSource`1 retry, DbConnectionOptions userOptions)
   en System.Data.SqlClient.SqlConnection.TryOpenInner(TaskCompletionSource`1 retry)
   en System.Data.SqlClient.SqlConnection.TryOpen(TaskCompletionSource`1 retry)
   en System.Data.SqlClient.SqlConnection.Open()
   en Umbraco.Core.Persistence.DbConnectionExtensions.IsAvailable(IDbConnection connection)
ClientConnectionId:00000000-0000-0000-0000-000000000000
Error Number:53,State:0,Class:20
 2019-09-18 07:44:40,027 [P18452/D2/T1] INFO  Umbraco.Core.DatabaseContext - CanConnect = False
 2019-09-18 07:44:41,028 [P18452/D2/T1] WARN  Umbraco.Core.Persistence.DbConnectionExtensions - Configured database is reporting as not being available! DataSource: 192.168.1.2, InitialCatalog: UMBRACOTESTING. Exception: System.Data.SqlClient.SqlException (0x80131904): Error relacionado con la red o específico de la instancia mientras se establecía una conexión con el servidor SQL Server. No se encontró el servidor o éste no estaba accesible. Compruebe que el nombre de la instancia es correcto y que SQL Server está configurado para admitir conexiones remotas. (provider: Named Pipes Provider, error: 40 - No se pudo abrir una conexión con SQL Server) ---> System.ComponentModel.Win32Exception (0x80004005): No se ha encontrado la ruta de acceso de la red
   en System.Data.ProviderBase.DbConnectionPool.TryGetConnection(DbConnection owningObject, UInt32 waitForMultipleObjectsTimeout, Boolean allowCreate, Boolean onlyOneCheckConnection, DbConnectionOptions userOptions, DbConnectionInternal& connection)
   en System.Data.ProviderBase.DbConnectionPool.TryGetConnection(DbConnection owningObject, TaskCompletionSource`1 retry, DbConnectionOptions userOptions, DbConnectionInternal& connection)
   en System.Data.ProviderBase.DbConnectionFactory.TryGetConnection(DbConnection owningConnection, TaskCompletionSource`1 retry, DbConnectionOptions userOptions, DbConnectionInternal oldConnection, DbConnectionInternal& connection)
   en System.Data.ProviderBase.DbConnectionInternal.TryOpenConnectionInternal(DbConnection outerConnection, DbConnectionFactory connectionFactory, TaskCompletionSource`1 retry, DbConnectionOptions userOptions)
   en System.Data.ProviderBase.DbConnectionClosed.TryOpenConnection(DbConnection outerConnection, DbConnectionFactory connectionFactory, TaskCompletionSource`1 retry, DbConnectionOptions userOptions)
   en System.Data.SqlClient.SqlConnection.TryOpenInner(TaskCompletionSource`1 retry)
   en System.Data.SqlClient.SqlConnection.TryOpen(TaskCompletionSource`1 retry)
   en System.Data.SqlClient.SqlConnection.Open()
   en Umbraco.Core.Persistence.DbConnectionExtensions.IsAvailable(IDbConnection connection)
ClientConnectionId:00000000-0000-0000-0000-000000000000
Error Number:53,State:0,Class:20
 2019-09-18 07:44:41,028 [P18452/D2/T1] INFO  Umbraco.Core.DatabaseContext - CanConnect = False
 2019-09-18 07:44:42,029 [P18452/D2/T1] WARN  Umbraco.Core.Persistence.DbConnectionExtensions - Configured database is reporting as not being available! DataSource: 192.168.1.2, InitialCatalog: UMBRACOTESTING. Exception: System.Data.SqlClient.SqlException (0x80131904): Error relacionado con la red o específico de la instancia mientras se establecía una conexión con el servidor SQL Server. No se encontró el servidor o éste no estaba accesible. Compruebe que el nombre de la instancia es correcto y que SQL Server está configurado para admitir conexiones remotas. (provider: Named Pipes Provider, error: 40 - No se pudo abrir una conexión con SQL Server) ---> System.ComponentModel.Win32Exception (0x80004005): No se ha encontrado la ruta de acceso de la red
   en System.Data.ProviderBase.DbConnectionPool.TryGetConnection(DbConnection owningObject, UInt32 waitForMultipleObjectsTimeout, Boolean allowCreate, Boolean onlyOneCheckConnection, DbConnectionOptions userOptions, DbConnectionInternal& connection)
   en System.Data.ProviderBase.DbConnectionPool.TryGetConnection(DbConnection owningObject, TaskCompletionSource`1 retry, DbConnectionOptions userOptions, DbConnectionInternal& connection)
   en System.Data.ProviderBase.DbConnectionFactory.TryGetConnection(DbConnection owningConnection, TaskCompletionSource`1 retry, DbConnectionOptions userOptions, DbConnectionInternal oldConnection, DbConnectionInternal& connection)
   en System.Data.ProviderBase.DbConnectionInternal.TryOpenConnectionInternal(DbConnection outerConnection, DbConnectionFactory connectionFactory, TaskCompletionSource`1 retry, DbConnectionOptions userOptions)
   en System.Data.ProviderBase.DbConnectionClosed.TryOpenConnection(DbConnection outerConnection, DbConnectionFactory connectionFactory, TaskCompletionSource`1 retry, DbConnectionOptions userOptions)
   en System.Data.SqlClient.SqlConnection.TryOpenInner(TaskCompletionSource`1 retry)
   en System.Data.SqlClient.SqlConnection.TryOpen(TaskCompletionSource`1 retry)
   en System.Data.SqlClient.SqlConnection.Open()
   en Umbraco.Core.Persistence.DbConnectionExtensions.IsAvailable(IDbConnection connection)
ClientConnectionId:00000000-0000-0000-0000-000000000000
Error Number:53,State:0,Class:20
 2019-09-18 07:44:42,029 [P18452/D2/T1] INFO  Umbraco.Core.DatabaseContext - CanConnect = False
 2019-09-18 07:44:58,370 [P18452/D2/T1] WARN  Umbraco.Core.Persistence.DbConnectionExtensions - Configured database is reporting as not being available! DataSource: 192.168.1.2, InitialCatalog: UMBRACOTESTING. Exception: System.Data.SqlClient.SqlException (0x80131904): Error relacionado con la red o específico de la instancia mientras se establecía una conexión con el servidor SQL Server. No se encontró el servidor o éste no estaba accesible. Compruebe que el nombre de la instancia es correcto y que SQL Server está configurado para admitir conexiones remotas. (provider: Named Pipes Provider, error: 40 - No se pudo abrir una conexión con SQL Server) ---> System.ComponentModel.Win32Exception (0x80004005): No se ha encontrado la ruta de acceso de la red
   en System.Data.SqlClient.SqlInternalConnectionTds..ctor(DbConnectionPoolIdentity identity, SqlConnectionString connectionOptions, SqlCredential credential, Object providerInfo, String newPassword, SecureString newSecurePassword, Boolean redirectedUserInstance, SqlConnectionString userConnectionOptions, SessionData reconnectSessionData, DbConnectionPool pool, String accessToken, Boolean applyTransientFaultHandling, SqlAuthenticationProviderManager sqlAuthProviderManager)
   en System.Data.SqlClient.SqlConnectionFactory.CreateConnection(DbConnectionOptions options, DbConnectionPoolKey poolKey, Object poolGroupProviderInfo, DbConnectionPool pool, DbConnection owningConnection, DbConnectionOptions userOptions)
   en System.Data.ProviderBase.DbConnectionFactory.CreatePooledConnection(DbConnectionPool pool, DbConnection owningObject, DbConnectionOptions options, DbConnectionPoolKey poolKey, DbConnectionOptions userOptions)
   en System.Data.ProviderBase.DbConnectionPool.CreateObject(DbConnection owningObject, DbConnectionOptions userOptions, DbConnectionInternal oldConnection)
   en System.Data.ProviderBase.DbConnectionPool.UserCreateRequest(DbConnection owningObject, DbConnectionOptions userOptions, DbConnectionInternal oldConnection)
   en System.Data.ProviderBase.DbConnectionPool.TryGetConnection(DbConnection owningObject, UInt32 waitForMultipleObjectsTimeout, Boolean allowCreate, Boolean onlyOneCheckConnection, DbConnectionOptions userOptions, DbConnectionInternal& connection)
   en System.Data.ProviderBase.DbConnectionPool.TryGetConnection(DbConnection owningObject, TaskCompletionSource`1 retry, DbConnectionOptions userOptions, DbConnectionInternal& connection)
   en System.Data.ProviderBase.DbConnectionFactory.TryGetConnection(DbConnection owningConnection, TaskCompletionSource`1 retry, DbConnectionOptions userOptions, DbConnectionInternal oldConnection, DbConnectionInternal& connection)
   en System.Data.ProviderBase.DbConnectionInternal.TryOpenConnectionInternal(DbConnection outerConnection, DbConnectionFactory connectionFactory, TaskCompletionSource`1 retry, DbConnectionOptions userOptions)
   en System.Data.ProviderBase.DbConnectionClosed.TryOpenConnection(DbConnection outerConnection, DbConnectionFactory connectionFactory, TaskCompletionSource`1 retry, DbConnectionOptions userOptions)
   en System.Data.SqlClient.SqlConnection.TryOpenInner(TaskCompletionSource`1 retry)
   en System.Data.SqlClient.SqlConnection.TryOpen(TaskCompletionSource`1 retry)
   en System.Data.SqlClient.SqlConnection.Open()
   en Umbraco.Core.Persistence.DbConnectionExtensions.IsAvailable(IDbConnection connection)
ClientConnectionId:00000000-0000-0000-0000-000000000000
Error Number:53,State:0,Class:20
 2019-09-18 07:44:58,372 [P18452/D2/T1] INFO  Umbraco.Core.DatabaseContext - CanConnect = False
 2019-09-18 07:44:58,384 [P18452/D2/T1] ERROR Umbraco.Core.UmbracoApplicationBase - An unhandled exception occurred
Umbraco.Core.Exceptions.UmbracoStartupFailedException: Umbraco cannot start. A connection string is configured but Umbraco cannot connect to the database.
   en Umbraco.Core.CoreBootManager.EnsureDatabaseConnection()
   en Umbraco.Core.CoreBootManager.Complete(Action`1 afterComplete)
   en Umbraco.Web.WebBootManager.Complete(Action`1 afterComplete)
   en Umbraco.Core.UmbracoApplicationBase.StartApplication(Object sender, EventArgs e)
   en Umbraco.Core.UmbracoApplicationBase.Application_Start(Object sender, EventArgs e)
 2019-09-18 07:45:08,409 [P18452/D2/T5] INFO  Umbraco.Core.MainDom - Stopping...
 2019-09-18 07:45:08,411 [P18452/D2/T5] INFO  Umbraco.Web.ExamineStartup - Examine shutting down
 2019-09-18 07:45:08,609 [P18452/D2/T5] INFO  Umbraco.Web.ExamineStartup - Complete (took 197ms)
 2019-09-18 07:45:08,610 [P18452/D2/T5] INFO  Umbraco.Core.MainDom - Released MainDom.
 2019-09-18 07:45:08,651 [P18452/D2/T6] INFO  Umbraco.Core.UmbracoApplicationBase - Application shutdown. Details: InitializationError

_shutDownMessage=Initialization Error
HostingEnvironment initiated shutdown
HostingEnvironment originó el cierre

_shutDownStack=   en System.Environment.GetStackTrace(Exception e, Boolean needFileInfo)
   en System.Environment.get_StackTrace()
   en System.Web.Hosting.HostingEnvironment.InitiateShutdownInternal()
   en System.Web.Hosting.HostingEnvironment.InitiateShutdownWithoutDemand()
   en System.Web.HttpRuntime.ShutdownAppDomain(String stackTrace)
   en System.Web.HttpRuntime.AppDomainShutdownTimerCallback(Object state)
   en System.Threading.TimerQueueTimer.CallCallbackInContext(Object state)
   en System.Threading.ExecutionContext.RunInternal(ExecutionContext executionContext, ContextCallback callback, Object state, Boolean preserveSyncCtx)
   en System.Threading.ExecutionContext.Run(ExecutionContext executionContext, ContextCallback callback, Object state, Boolean preserveSyncCtx)
   en System.Threading.TimerQueueTimer.CallCallback()
   en System.Threading.TimerQueueTimer.Fire()
   en System.Threading.TimerQueue.FireNextTimers()
   en System.Threading.TimerQueue.AppDomainTimerCallback(Int32 id)
 2019-09-18 08:30:12,712 [P19472/D2/T1] INFO  Umbraco.Core.CoreBootManager - Umbraco 7.15.3 application starting on PTL10JCESCOBOSA
 2019-09-18 08:30:12,767 [P19472/D2/T1] INFO  Umbraco.Core.PluginManager - Determining hash of code files on disk
 2019-09-18 08:30:12,818 [P19472/D2/T1] INFO  Umbraco.Core.PluginManager - Hash determined (took 51ms)
 2019-09-18 08:30:12,974 [P19472/D2/T1] INFO  Umbraco.Core.MainDom - Acquiring MainDom...
 2019-09-18 08:30:12,979 [P19472/D2/T1] INFO  Umbraco.Core.MainDom - Acquired MainDom.
 2019-09-18 08:30:12,984 [P19472/D2/T1] INFO  Umbraco.Core.PluginManager - Resolving umbraco.interfaces.IDiscoverable
 2019-09-18 08:30:13,128 [P19472/D2/T1] INFO  Umbraco.Core.PluginManager - Resolved umbraco.interfaces.IDiscoverable (took 142ms)
 2019-09-18 08:30:13,128 [P19472/D2/T1] INFO  Umbraco.Core.PluginManager - Resolving umbraco.interfaces.IApplicationStartupHandler
 2019-09-18 08:30:13,133 [P19472/D2/T1] INFO  Umbraco.Core.PluginManager - Resolved umbraco.interfaces.IApplicationStartupHandler (took 5ms)
 2019-09-18 08:30:13,213 [P19472/D2/T1] INFO  Umbraco.Core.PluginManager - Resolving umbraco.interfaces.IDiscoverable
 2019-09-18 08:30:13,214 [P19472/D2/T1] INFO  Umbraco.Core.PluginManager - Resolved umbraco.interfaces.IDiscoverable (took 1ms)
 2019-09-18 08:30:13,215 [P19472/D2/T1] INFO  Umbraco.Core.PluginManager - Resolving Umbraco.Core.PropertyEditors.IPropertyEditorValueConverter
 2019-09-18 08:30:13,216 [P19472/D2/T1] INFO  Umbraco.Core.PluginManager - Resolved Umbraco.Core.PropertyEditors.IPropertyEditorValueConverter (took 1ms)
 2019-09-18 08:30:13,217 [P19472/D2/T1] INFO  Umbraco.Core.PluginManager - Resolving umbraco.interfaces.IDiscoverable
 2019-09-18 08:30:13,217 [P19472/D2/T1] INFO  Umbraco.Core.PluginManager - Resolved umbraco.interfaces.IDiscoverable (took 0ms)
 2019-09-18 08:30:13,219 [P19472/D2/T1] INFO  Umbraco.Core.PluginManager - Resolving Umbraco.Core.PropertyEditors.IPropertyValueConverter
 2019-09-18 08:30:13,224 [P19472/D2/T1] INFO  Umbraco.Core.PluginManager - Resolved Umbraco.Core.PropertyEditors.IPropertyValueConverter (took 4ms)
 2019-09-18 08:30:13,268 [P19472/D2/T1] INFO  Umbraco.Core.PluginManager - Resolving umbraco.interfaces.IDiscoverable
 2019-09-18 08:30:13,268 [P19472/D2/T1] INFO  Umbraco.Core.PluginManager - Resolved umbraco.interfaces.IDiscoverable (took 0ms)
 2019-09-18 08:30:13,269 [P19472/D2/T1] INFO  Umbraco.Core.PluginManager - Resolving Umbraco.Web.Mvc.SurfaceController
 2019-09-18 08:30:13,270 [P19472/D2/T1] INFO  Umbraco.Core.PluginManager - Resolved Umbraco.Web.Mvc.SurfaceController (took 1ms)
 2019-09-18 08:30:13,271 [P19472/D2/T1] INFO  Umbraco.Core.PluginManager - Resolving umbraco.interfaces.IDiscoverable
 2019-09-18 08:30:13,272 [P19472/D2/T1] INFO  Umbraco.Core.PluginManager - Resolved umbraco.interfaces.IDiscoverable (took 0ms)
 2019-09-18 08:30:13,272 [P19472/D2/T1] INFO  Umbraco.Core.PluginManager - Resolving Umbraco.Web.WebApi.UmbracoApiController
 2019-09-18 08:30:13,276 [P19472/D2/T1] INFO  Umbraco.Core.PluginManager - Resolved Umbraco.Web.WebApi.UmbracoApiController (took 3ms)
 2019-09-18 08:30:45,350 [P19472/D2/T1] WARN  Umbraco.Core.Persistence.DbConnectionExtensions - Configured database is reporting as not being available! DataSource: 192.168.1.2, InitialCatalog: UMBRACOTESTING. Exception: System.Data.SqlClient.SqlException (0x80131904): Error relacionado con la red o específico de la instancia mientras se establecía una conexión con el servidor SQL Server. No se encontró el servidor o éste no estaba accesible. Compruebe que el nombre de la instancia es correcto y que SQL Server está configurado para admitir conexiones remotas. (provider: Named Pipes Provider, error: 40 - No se pudo abrir una conexión con SQL Server) ---> System.ComponentModel.Win32Exception (0x80004005): No se ha encontrado la ruta de acceso de la red
   en System.Data.SqlClient.SqlInternalConnectionTds..ctor(DbConnectionPoolIdentity identity, SqlConnectionString connectionOptions, SqlCredential credential, Object providerInfo, String newPassword, SecureString newSecurePassword, Boolean redirectedUserInstance, SqlConnectionString userConnectionOptions, SessionData reconnectSessionData, DbConnectionPool pool, String accessToken, Boolean applyTransientFaultHandling, SqlAuthenticationProviderManager sqlAuthProviderManager)
   en System.Data.SqlClient.SqlConnectionFactory.CreateConnection(DbConnectionOptions options, DbConnectionPoolKey poolKey, Object poolGroupProviderInfo, DbConnectionPool pool, DbConnection owningConnection, DbConnectionOptions userOptions)
   en System.Data.ProviderBase.DbConnectionFactory.CreatePooledConnection(DbConnectionPool pool, DbConnection owningObject, DbConnectionOptions options, DbConnectionPoolKey poolKey, DbConnectionOptions userOptions)
   en System.Data.ProviderBase.DbConnectionPool.CreateObject(DbConnection owningObject, DbConnectionOptions userOptions, DbConnectionInternal oldConnection)
   en System.Data.ProviderBase.DbConnectionPool.UserCreateRequest(DbConnection owningObject, DbConnectionOptions userOptions, DbConnectionInternal oldConnection)
   en System.Data.ProviderBase.DbConnectionPool.TryGetConnection(DbConnection owningObject, UInt32 waitForMultipleObjectsTimeout, Boolean allowCreate, Boolean onlyOneCheckConnection, DbConnectionOptions userOptions, DbConnectionInternal& connection)
   en System.Data.ProviderBase.DbConnectionPool.TryGetConnection(DbConnection owningObject, TaskCompletionSource`1 retry, DbConnectionOptions userOptions, DbConnectionInternal& connection)
   en System.Data.ProviderBase.DbConnectionFactory.TryGetConnection(DbConnection owningConnection, TaskCompletionSource`1 retry, DbConnectionOptions userOptions, DbConnectionInternal oldConnection, DbConnectionInternal& connection)
   en System.Data.ProviderBase.DbConnectionInternal.TryOpenConnectionInternal(DbConnection outerConnection, DbConnectionFactory connectionFactory, TaskCompletionSource`1 retry, DbConnectionOptions userOptions)
   en System.Data.SqlClient.SqlConnection.TryOpenInner(TaskCompletionSource`1 retry)
   en System.Data.SqlClient.SqlConnection.TryOpen(TaskCompletionSource`1 retry)
   en System.Data.SqlClient.SqlConnection.Open()
   en Umbraco.Core.Persistence.DbConnectionExtensions.IsAvailable(IDbConnection connection)
ClientConnectionId:00000000-0000-0000-0000-000000000000
Error Number:53,State:0,Class:20
 2019-09-18 08:30:45,352 [P19472/D2/T1] INFO  Umbraco.Core.DatabaseContext - CanConnect = False
 2019-09-18 08:30:45,855 [P19472/D2/T1] WARN  Umbraco.Core.Persistence.DbConnectionExtensions - Configured database is reporting as not being available! DataSource: 192.168.1.2, InitialCatalog: UMBRACOTESTING. Exception: System.Data.SqlClient.SqlException (0x80131904): Error relacionado con la red o específico de la instancia mientras se establecía una conexión con el servidor SQL Server. No se encontró el servidor o éste no estaba accesible. Compruebe que el nombre de la instancia es correcto y que SQL Server está configurado para admitir conexiones remotas. (provider: Named Pipes Provider, error: 40 - No se pudo abrir una conexión con SQL Server) ---> System.ComponentModel.Win32Exception (0x80004005): No se ha encontrado la ruta de acceso de la red
   en System.Data.ProviderBase.DbConnectionPool.TryGetConnection(DbConnection owningObject, UInt32 waitForMultipleObjectsTimeout, Boolean allowCreate, Boolean onlyOneCheckConnection, DbConnectionOptions userOptions, DbConnectionInternal& connection)
   en System.Data.ProviderBase.DbConnectionPool.TryGetConnection(DbConnection owningObject, TaskCompletionSource`1 retry, DbConnectionOptions userOptions, DbConnectionInternal& connection)
   en System.Data.ProviderBase.DbConnectionFactory.TryGetConnection(DbConnection owningConnection, TaskCompletionSource`1 retry, DbConnectionOptions userOptions, DbConnectionInternal oldConnection, DbConnectionInternal& connection)
   en System.Data.ProviderBase.DbConnectionInternal.TryOpenConnectionInternal(DbConnection outerConnection, DbConnectionFactory connectionFactory, TaskCompletionSource`1 retry, DbConnectionOptions userOptions)
   en System.Data.SqlClient.SqlConnection.TryOpenInner(TaskCompletionSource`1 retry)
   en System.Data.SqlClient.SqlConnection.TryOpen(TaskCompletionSource`1 retry)
   en System.Data.SqlClient.SqlConnection.Open()
   en Umbraco.Core.Persistence.DbConnectionExtensions.IsAvailable(IDbConnection connection)
ClientConnectionId:00000000-0000-0000-0000-000000000000
Error Number:53,State:0,Class:20
 2019-09-18 08:30:45,855 [P19472/D2/T1] INFO  Umbraco.Core.DatabaseContext - CanConnect = False
 2019-09-18 08:30:46,862 [P19472/D2/T1] WARN  Umbraco.Core.Persistence.DbConnectionExtensions - Configured database is reporting as not being available! DataSource: 192.168.1.2, InitialCatalog: UMBRACOTESTING. Exception: System.Data.SqlClient.SqlException (0x80131904): Error relacionado con la red o específico de la instancia mientras se establecía una conexión con el servidor SQL Server. No se encontró el servidor o éste no estaba accesible. Compruebe que el nombre de la instancia es correcto y que SQL Server está configurado para admitir conexiones remotas. (provider: Named Pipes Provider, error: 40 - No se pudo abrir una conexión con SQL Server) ---> System.ComponentModel.Win32Exception (0x80004005): No se ha encontrado la ruta de acceso de la red
   en System.Data.ProviderBase.DbConnectionPool.TryGetConnection(DbConnection owningObject, UInt32 waitForMultipleObjectsTimeout, Boolean allowCreate, Boolean onlyOneCheckConnection, DbConnectionOptions userOptions, DbConnectionInternal& connection)
   en System.Data.ProviderBase.DbConnectionPool.TryGetConnection(DbConnection owningObject, TaskCompletionSource`1 retry, DbConnectionOptions userOptions, DbConnectionInternal& connection)
   en System.Data.ProviderBase.DbConnectionFactory.TryGetConnection(DbConnection owningConnection, TaskCompletionSource`1 retry, DbConnectionOptions userOptions, DbConnectionInternal oldConnection, DbConnectionInternal& connection)
   en System.Data.ProviderBase.DbConnectionInternal.TryOpenConnectionInternal(DbConnection outerConnection, DbConnectionFactory connectionFactory, TaskCompletionSource`1 retry, DbConnectionOptions userOptions)
   en System.Data.SqlClient.SqlConnection.TryOpenInner(TaskCompletionSource`1 retry)
   en System.Data.SqlClient.SqlConnection.TryOpen(TaskCompletionSource`1 retry)
   en System.Data.SqlClient.SqlConnection.Open()
   en Umbraco.Core.Persistence.DbConnectionExtensions.IsAvailable(IDbConnection connection)
ClientConnectionId:00000000-0000-0000-0000-000000000000
Error Number:53,State:0,Class:20
 2019-09-18 08:30:46,863 [P19472/D2/T1] INFO  Umbraco.Core.DatabaseContext - CanConnect = False
 2019-09-18 08:30:47,864 [P19472/D2/T1] WARN  Umbraco.Core.Persistence.DbConnectionExtensions - Configured database is reporting as not being available! DataSource: 192.168.1.2, InitialCatalog: UMBRACOTESTING. Exception: System.Data.SqlClient.SqlException (0x80131904): Error relacionado con la red o específico de la instancia mientras se establecía una conexión con el servidor SQL Server. No se encontró el servidor o éste no estaba accesible. Compruebe que el nombre de la instancia es correcto y que SQL Server está configurado para admitir conexiones remotas. (provider: Named Pipes Provider, error: 40 - No se pudo abrir una conexión con SQL Server) ---> System.ComponentModel.Win32Exception (0x80004005): No se ha encontrado la ruta de acceso de la red
   en System.Data.ProviderBase.DbConnectionPool.TryGetConnection(DbConnection owningObject, UInt32 waitForMultipleObjectsTimeout, Boolean allowCreate, Boolean onlyOneCheckConnection, DbConnectionOptions userOptions, DbConnectionInternal& connection)
   en System.Data.ProviderBase.DbConnectionPool.TryGetConnection(DbConnection owningObject, TaskCompletionSource`1 retry, DbConnectionOptions userOptions, DbConnectionInternal& connection)
   en System.Data.ProviderBase.DbConnectionFactory.TryGetConnection(DbConnection owningConnection, TaskCompletionSource`1 retry, DbConnectionOptions userOptions, DbConnectionInternal oldConnection, DbConnectionInternal& connection)
   en System.Data.ProviderBase.DbConnectionInternal.TryOpenConnectionInternal(DbConnection outerConnection, DbConnectionFactory connectionFactory, TaskCompletionSource`1 retry, DbConnectionOptions userOptions)
   en System.Data.SqlClient.SqlConnection.TryOpenInner(TaskCompletionSource`1 retry)
   en System.Data.SqlClient.SqlConnection.TryOpen(TaskCompletionSource`1 retry)
   en System.Data.SqlClient.SqlConnection.Open()
   en Umbraco.Core.Persistence.DbConnectionExtensions.IsAvailable(IDbConnection connection)
ClientConnectionId:00000000-0000-0000-0000-000000000000
Error Number:53,State:0,Class:20
 2019-09-18 08:30:47,864 [P19472/D2/T1] INFO  Umbraco.Core.DatabaseContext - CanConnect = False
 2019-09-18 08:30:48,868 [P19472/D2/T1] WARN  Umbraco.Core.Persistence.DbConnectionExtensions - Configured database is reporting as not being available! DataSource: 192.168.1.2, InitialCatalog: UMBRACOTESTING. Exception: System.Data.SqlClient.SqlException (0x80131904): Error relacionado con la red o específico de la instancia mientras se establecía una conexión con el servidor SQL Server. No se encontró el servidor o éste no estaba accesible. Compruebe que el nombre de la instancia es correcto y que SQL Server está configurado para admitir conexiones remotas. (provider: Named Pipes Provider, error: 40 - No se pudo abrir una conexión con SQL Server) ---> System.ComponentModel.Win32Exception (0x80004005): No se ha encontrado la ruta de acceso de la red
   en System.Data.ProviderBase.DbConnectionPool.TryGetConnection(DbConnection owningObject, UInt32 waitForMultipleObjectsTimeout, Boolean allowCreate, Boolean onlyOneCheckConnection, DbConnectionOptions userOptions, DbConnectionInternal& connection)
   en System.Data.ProviderBase.DbConnectionPool.TryGetConnection(DbConnection owningObject, TaskCompletionSource`1 retry, DbConnectionOptions userOptions, DbConnectionInternal& connection)
   en System.Data.ProviderBase.DbConnectionFactory.TryGetConnection(DbConnection owningConnection, TaskCompletionSource`1 retry, DbConnectionOptions userOptions, DbConnectionInternal oldConnection, DbConnectionInternal& connection)
   en System.Data.ProviderBase.DbConnectionInternal.TryOpenConnectionInternal(DbConnection outerConnection, DbConnectionFactory connectionFactory, TaskCompletionSource`1 retry, DbConnectionOptions userOptions)
   en System.Data.SqlClient.SqlConnection.TryOpenInner(TaskCompletionSource`1 retry)
   en System.Data.SqlClient.SqlConnection.TryOpen(TaskCompletionSource`1 retry)
   en System.Data.SqlClient.SqlConnection.Open()
   en Umbraco.Core.Persistence.DbConnectionExtensions.IsAvailable(IDbConnection connection)
ClientConnectionId:00000000-0000-0000-0000-000000000000
Error Number:53,State:0,Class:20
 2019-09-18 08:30:48,869 [P19472/D2/T1] INFO  Umbraco.Core.DatabaseContext - CanConnect = False
 2019-09-18 08:30:49,884 [P19472/D2/T1] WARN  Umbraco.Core.Persistence.DbConnectionExtensions - Configured database is reporting as not being available! DataSource: 192.168.1.2, InitialCatalog: UMBRACOTESTING. Exception: System.Data.SqlClient.SqlException (0x80131904): Error relacionado con la red o específico de la instancia mientras se establecía una conexión con el servidor SQL Server. No se encontró el servidor o éste no estaba accesible. Compruebe que el nombre de la instancia es correcto y que SQL Server está configurado para admitir conexiones remotas. (provider: Named Pipes Provider, error: 40 - No se pudo abrir una conexión con SQL Server) ---> System.ComponentModel.Win32Exception (0x80004005): No se ha encontrado la ruta de acceso de la red
   en System.Data.ProviderBase.DbConnectionPool.TryGetConnection(DbConnection owningObject, UInt32 waitForMultipleObjectsTimeout, Boolean allowCreate, Boolean onlyOneCheckConnection, DbConnectionOptions userOptions, DbConnectionInternal& connection)
   en System.Data.ProviderBase.DbConnectionPool.TryGetConnection(DbConnection owningObject, TaskCompletionSource`1 retry, DbConnectionOptions userOptions, DbConnectionInternal& connection)
   en System.Data.ProviderBase.DbConnectionFactory.TryGetConnection(DbConnection owningConnection, TaskCompletionSource`1 retry, DbConnectionOptions userOptions, DbConnectionInternal oldConnection, DbConnectionInternal& connection)
   en System.Data.ProviderBase.DbConnectionInternal.TryOpenConnectionInternal(DbConnection outerConnection, DbConnectionFactory connectionFactory, TaskCompletionSource`1 retry, DbConnectionOptions userOptions)
   en System.Data.SqlClient.SqlConnection.TryOpenInner(TaskCompletionSource`1 retry)
   en System.Data.SqlClient.SqlConnection.TryOpen(TaskCompletionSource`1 retry)
   en System.Data.SqlClient.SqlConnection.Open()
   en Umbraco.Core.Persistence.DbConnectionExtensions.IsAvailable(IDbConnection connection)
ClientConnectionId:00000000-0000-0000-0000-000000000000
Error Number:53,State:0,Class:20
 2019-09-18 08:30:49,885 [P19472/D2/T1] INFO  Umbraco.Core.DatabaseContext - CanConnect = False
 2019-09-18 08:31:06,217 [P19472/D2/T1] WARN  Umbraco.Core.Persistence.DbConnectionExtensions - Configured database is reporting as not being available! DataSource: 192.168.1.2, InitialCatalog: UMBRACOTESTING. Exception: System.Data.SqlClient.SqlException (0x80131904): Error relacionado con la red o específico de la instancia mientras se establecía una conexión con el servidor SQL Server. No se encontró el servidor o éste no estaba accesible. Compruebe que el nombre de la instancia es correcto y que SQL Server está configurado para admitir conexiones remotas. (provider: Named Pipes Provider, error: 40 - No se pudo abrir una conexión con SQL Server) ---> System.ComponentModel.Win32Exception (0x80004005): No se ha encontrado la ruta de acceso de la red
   en System.Data.SqlClient.SqlInternalConnectionTds..ctor(DbConnectionPoolIdentity identity, SqlConnectionString connectionOptions, SqlCredential credential, Object providerInfo, String newPassword, SecureString newSecurePassword, Boolean redirectedUserInstance, SqlConnectionString userConnectionOptions, SessionData reconnectSessionData, DbConnectionPool pool, String accessToken, Boolean applyTransientFaultHandling, SqlAuthenticationProviderManager sqlAuthProviderManager)
   en System.Data.SqlClient.SqlConnectionFactory.CreateConnection(DbConnectionOptions options, DbConnectionPoolKey poolKey, Object poolGroupProviderInfo, DbConnectionPool pool, DbConnection owningConnection, DbConnectionOptions userOptions)
   en System.Data.ProviderBase.DbConnectionFactory.CreatePooledConnection(DbConnectionPool pool, DbConnection owningObject, DbConnectionOptions options, DbConnectionPoolKey poolKey, DbConnectionOptions userOptions)
   en System.Data.ProviderBase.DbConnectionPool.CreateObject(DbConnection owningObject, DbConnectionOptions userOptions, DbConnectionInternal oldConnection)
   en System.Data.ProviderBase.DbConnectionPool.UserCreateRequest(DbConnection owningObject, DbConnectionOptions userOptions, DbConnectionInternal oldConnection)
   en System.Data.ProviderBase.DbConnectionPool.TryGetConnection(DbConnection owningObject, UInt32 waitForMultipleObjectsTimeout, Boolean allowCreate, Boolean onlyOneCheckConnection, DbConnectionOptions userOptions, DbConnectionInternal& connection)
   en System.Data.ProviderBase.DbConnectionPool.TryGetConnection(DbConnection owningObject, TaskCompletionSource`1 retry, DbConnectionOptions userOptions, DbConnectionInternal& connection)
   en System.Data.ProviderBase.DbConnectionFactory.TryGetConnection(DbConnection owningConnection, TaskCompletionSource`1 retry, DbConnectionOptions userOptions, DbConnectionInternal oldConnection, DbConnectionInternal& connection)
   en System.Data.ProviderBase.DbConnectionInternal.TryOpenConnectionInternal(DbConnection outerConnection, DbConnectionFactory connectionFactory, TaskCompletionSource`1 retry, DbConnectionOptions userOptions)
   en System.Data.SqlClient.SqlConnection.TryOpenInner(TaskCompletionSource`1 retry)
   en System.Data.SqlClient.SqlConnection.TryOpen(TaskCompletionSource`1 retry)
   en System.Data.SqlClient.SqlConnection.Open()
   en Umbraco.Core.Persistence.DbConnectionExtensions.IsAvailable(IDbConnection connection)
ClientConnectionId:00000000-0000-0000-0000-000000000000
Error Number:53,State:0,Class:20
 2019-09-18 08:31:06,217 [P19472/D2/T1] INFO  Umbraco.Core.DatabaseContext - CanConnect = False
 2019-09-18 08:31:06,231 [P19472/D2/T1] ERROR Umbraco.Core.UmbracoApplicationBase - An unhandled exception occurred
Umbraco.Core.Exceptions.UmbracoStartupFailedException: Umbraco cannot start. A connection string is configured but Umbraco cannot connect to the database.
   en Umbraco.Core.CoreBootManager.EnsureDatabaseConnection()
   en Umbraco.Core.CoreBootManager.Complete(Action`1 afterComplete)
   en Umbraco.Web.WebBootManager.Complete(Action`1 afterComplete)
   en Umbraco.Core.UmbracoApplicationBase.StartApplication(Object sender, EventArgs e)
 2019-09-18 08:31:16,317 [P19472/D2/T7] INFO  Umbraco.Core.MainDom - Stopping...
 2019-09-18 08:31:16,323 [P19472/D2/T7] INFO  Umbraco.Web.ExamineStartup - Examine shutting down
 2019-09-18 08:31:17,081 [P19472/D2/T7] INFO  Umbraco.Web.ExamineStartup - Complete (took 758ms)
 2019-09-18 08:31:17,082 [P19472/D2/T7] INFO  Umbraco.Core.MainDom - Released MainDom.
 2019-09-18 08:31:17,187 [P19472/D2/T8] INFO  Umbraco.Core.UmbracoApplicationBase - Application shutdown. Details: InitializationError

_shutDownMessage=Initialization Error
HostingEnvironment initiated shutdown
HostingEnvironment originó el cierre

_shutDownStack=   en System.Environment.GetStackTrace(Exception e, Boolean needFileInfo)
   en System.Environment.get_StackTrace()
   en System.Web.Hosting.HostingEnvironment.InitiateShutdownInternal()
   en System.Web.Hosting.HostingEnvironment.InitiateShutdownWithoutDemand()
   en System.Web.HttpRuntime.ShutdownAppDomain(String stackTrace)
   en System.Web.HttpRuntime.AppDomainShutdownTimerCallback(Object state)
   en System.Threading.ExecutionContext.RunInternal(ExecutionContext executionContext, ContextCallback callback, Object state, Boolean preserveSyncCtx)
   en System.Threading.ExecutionContext.Run(ExecutionContext executionContext, ContextCallback callback, Object state, Boolean preserveSyncCtx)
   en System.Threading.TimerQueueTimer.CallCallback()
   en System.Threading.TimerQueueTimer.Fire()
   en System.Threading.TimerQueue.FireNextTimers()
